Traceback (most recent call last):
  File "/home/will/MyFirstAI/venv/lib/python3.10/site-packages/wandb/sdk/wandb_config.py", line 162, in __getattr__
    return self.__getitem__(key)
  File "/home/will/MyFirstAI/venv/lib/python3.10/site-packages/wandb/sdk/wandb_config.py", line 130, in __getitem__
    return self._items[key]
KeyError: 'embed_size'
The above exception was the direct cause of the following exception:
Traceback (most recent call last):
  File "/home/will/MyFirstAI/train.py", line 21, in train
    model = CNN_to_RNN(config.embed_size, config.hidden_size, config.vocab_size, config.num_layers).to(device)
  File "/home/will/MyFirstAI/venv/lib/python3.10/site-packages/wandb/sdk/wandb_config.py", line 164, in __getattr__
    raise AttributeError(
AttributeError: <class 'wandb.sdk.wandb_config.Config'> object has no attribute 'embed_size'